python : Traceback (most recent call last):
строка:1 знак:60
+ ... ock Tracker\Stock-Tracker'; python update_table_fixed.py 2>&1 | Out-F ...
+                                 ~~~~~~~~~~~~~~~~~~~~~~~~~~~~~~~~~
    + CategoryInfo          : NotSpecified: (Traceback (most recent call last)::String) [], Remot 
   eException
    + FullyQualifiedErrorId : NativeCommandError
 
  File "C:\Users\miros\Downloads\Stock Tracker\Stock-Tracker\update_table_fixed.py", line 48, in u
pdate_table_data_async
    print("\U0001f680 ������ ���������� ������� Stock Tracker")
    ~~~~~^^^^^^^^^^^^^^^^^^^^^^^^^^^^^^^^^^^^^^^^^^^^^^
  File "C:\Python313\Lib\encodings\cp1251.py", line 19, in encode
    return codecs.charmap_encode(input,self.errors,encoding_table)[0]
           ~~~~~~~~~~~~~~~~~~~~~^^^^^^^^^^^^^^^^^^^^^^^^^^^^^^^^^^
UnicodeEncodeError: 'charmap' codec can't encode character '\U0001f680' in position 0: character m
aps to <undefined>

During handling of the above exception, another exception occurred:

Traceback (most recent call last):
  File "C:\Users\miros\Downloads\Stock Tracker\Stock-Tracker\update_table_fixed.py", line 207, in 
<module>
    success = update_table_data(spreadsheet_id, worksheet_name)
  File "C:\Users\miros\Downloads\Stock Tracker\Stock-Tracker\update_table_fixed.py", line 151, in 
update_table_data
    return asyncio.run(update_table_data_async(spreadsheet_id, worksheet_name))
           ~~~~~~~~~~~^^^^^^^^^^^^^^^^^^^^^^^^^^^^^^^^^^^^^^^^^^^^^^^^^^^^^^^^^
  File "C:\Python313\Lib\asyncio\runners.py", line 195, in run
    return runner.run(main)
           ~~~~~~~~~~^^^^^^
  File "C:\Python313\Lib\asyncio\runners.py", line 118, in run
    return self._loop.run_until_complete(task)
           ~~~~~~~~~~~~~~~~~~~~~~~~~~~~~^^^^^^
  File "C:\Python313\Lib\asyncio\base_events.py", line 725, in run_until_complete
    return future.result()
           ~~~~~~~~~~~~~^^
  File "C:\Users\miros\Downloads\Stock Tracker\Stock-Tracker\update_table_fixed.py", line 133, in 
update_table_data_async
    print(f"\n\u274c ����������� ������ ��� ���������� �������: {e}")
    ~~~~~^^^^^^^^^^^^^^^^^^^^^^^^^^^^^^^^^^^^^^^^^^^^^^^^^^^^^^^^
  File "C:\Python313\Lib\encodings\cp1251.py", line 19, in encode
    return codecs.charmap_encode(input,self.errors,encoding_table)[0]
           ~~~~~~~~~~~~~~~~~~~~~^^^^^^^^^^^^^^^^^^^^^^^^^^^^^^^^^^
UnicodeEncodeError: 'charmap' codec can't encode character '\u274c' in position 2: character maps 
to <undefined>

During handling of the above exception, another exception occurred:

Traceback (most recent call last):
  File "C:\Users\miros\Downloads\Stock Tracker\Stock-Tracker\update_table_fixed.py", line 221, in 
<module>
    print(f"\n\U0001f4a5 ����������� ������: {e}")
    ~~~~~^^^^^^^^^^^^^^^^^^^^^^^^^^^^^^^^^
  File "C:\Python313\Lib\encodings\cp1251.py", line 19, in encode
    return codecs.charmap_encode(input,self.errors,encoding_table)[0]
           ~~~~~~~~~~~~~~~~~~~~~^^^^^^^^^^^^^^^^^^^^^^^^^^^^^^^^^^
UnicodeEncodeError: 'charmap' codec can't encode character '\U0001f4a5' in position 2: character m
aps to <undefined>
